<?xml version="1.0" encoding="utf-8"?>
<!-- This URDF was automatically created by SolidWorks to URDF Exporter! Originally created by Stephen Brawner (brawner@gmail.com) 
     Commit Version: 1.6.0-4-g7f85cfe  Build Version: 1.6.7995.38578
     For more information, please see http://wiki.ros.org/sw_urdf_exporter -->
<robot
  name="robot">
  <link
    name="base_link">
    <inertial>
      <origin
        xyz="3.29597460435593E-17 0.0600600740935481 2.22044604925031E-16"
        rpy="0 0 0" />
      <mass
        value="20.4614601836601" />
      <inertia
        ixx="0.249216414234592"
        ixy="-1.6013655419642E-17"
        ixz="2.4740773598114E-17"
        iyy="0.6175648877969"
        iyz="-4.29674560252043E-17"
        izz="0.435038252585552" />
    </inertial>
    <visual>
      <origin
        xyz="0 0 0"
        rpy="0 0 0" />
      <geometry>
        <mesh
          filename="package://robot/meshes/base_link.STL" />
      </geometry>
      <material
        name="">
        <color
          rgba="1 1 1 1" />
      </material>
    </visual>
    <collision>
      <origin
        xyz="0 0 0"
        rpy="0 0 0" />
      <geometry>
        <mesh
          filename="package://robot/meshes/base_link.STL" />
      </geometry>
    </collision>
  </link>
  <link
    name="LB_1">
    <inertial>
      <origin
        xyz="-0.0912954643793855 -4.30211422042248E-16 0.0113056803430923"
        rpy="0 0 0" />
      <mass
        value="0.324823001646924" />
      <inertia
        ixx="0.000107013716905788"
        ixy="1.46984702766107E-19"
        ixz="-3.87197766270466E-05"
        iyy="0.00180263223873226"
        iyz="4.41635737594729E-20"
        izz="0.00187778887256759" />
    </inertial>
    <visual>
      <origin
        xyz="0 0 0"
        rpy="0 0 0" />
      <geometry>
        <mesh
          filename="package://robot/meshes/LB_1.STL" />
      </geometry>
      <material
        name="">
        <color
          rgba="1 1 1 1" />
      </material>
    </visual>
    <collision>
      <origin
        xyz="0 0 0"
        rpy="0 0 0" />
      <geometry>
        <mesh
          filename="package://robot/meshes/LB_1.STL" />
      </geometry>
    </collision>
  </link>
  <joint
    name="LB_1"
    type="revolute">
    <origin
      xyz="-0.05 0.08 -0.185"
      rpy="0 0 0" />
    <parent
      link="base_link" />
    <child
      link="LB_1" />
    <axis
      xyz="0 0 -1" />
    <limit
      lower="0.2617"
      upper="1.0466"
      effort="0"
      velocity="0" />
  </joint>
  <link
    name="LB_2">
    <inertial>
      <origin
        xyz="0.15 0 0.01"
        rpy="0 0 0" />
      <mass
        value="0.444823001646924" />
      <inertia
        ixx="0.000145446900494077"
        ixy="-3.08055646145075E-19"
        ixz="5.30143760293281E-05"
        iyy="0.00486196443754987"
        iyz="-8.24555454475602E-20"
        izz="0.00497068788779691" />
    </inertial>
    <visual>
      <origin
        xyz="0 0 0"
        rpy="0 0 0" />
      <geometry>
        <mesh
          filename="package://robot/meshes/LB_2.STL" />
      </geometry>
      <material
        name="">
        <color
          rgba="1 1 1 1" />
      </material>
    </visual>
    <collision>
      <origin
        xyz="0 0 0"
        rpy="0 0 0" />
      <geometry>
        <mesh
          filename="package://robot/meshes/LB_2.STL" />
      </geometry>
    </collision>
  </link>
  <joint
    name="LB_2"
    type="revolute">
    <origin
      xyz="-0.2 0 -0.025"
      rpy="0 0 -0.58569" />
    <parent
      link="LB_1" />
    <child
      link="LB_2" />
    <axis
      xyz="0 0 -1" />
    <limit
      lower="0"
      upper="0"
      effort="0"
      velocity="0" />
  </joint>
  <link
    name="LF_1">
    <inertial>
      <origin
        xyz="0.0749790246153097 5.96744875736022E-16 0.0168807682307895"
        rpy="0 0 0" />
      <mass
        value="0.395508836352695" />
      <inertia
        ixx="0.000183089900579248"
        ixy="1.34582027423028E-19"
        ixz="0.000204048265203773"
        iyy="0.0023625702698755"
        iyz="-1.3974866137207E-20"
        izz="0.00239345934565496" />
    </inertial>
    <visual>
      <origin
        xyz="0 0 0"
        rpy="0 0 0" />
      <geometry>
        <mesh
          filename="package://robot/meshes/LF_1.STL" />
      </geometry>
      <material
        name="">
        <color
          rgba="1 1 1 1" />
      </material>
    </visual>
    <collision>
      <origin
        xyz="0 0 0"
        rpy="0 0 0" />
      <geometry>
        <mesh
          filename="package://robot/meshes/LF_1.STL" />
      </geometry>
    </collision>
  </link>
  <joint
    name="LF_1"
    type="revolute">
    <origin
      xyz="0.05 0.08 -0.21"
      rpy="0 0 0" />
    <parent
      link="base_link" />
    <child
      link="LF_1" />
    <axis
      xyz="0 0 -1" />
    <limit
      lower="-0.2617"
      upper="-1.0466"
      effort="0"
      velocity="0" />
  </joint>
  <link
    name="LF_2">
    <inertial>
      <origin
        xyz="-0.15 -1.38777878078145E-17 0.01"
        rpy="0 0 0" />
      <mass
        value="0.444823001646924" />
      <inertia
        ixx="0.000145446900494078"
        ixy="-1.30943819243349E-20"
        ixz="-5.30143760293279E-05"
        iyy="0.00486196443754988"
        iyz="-9.34435693775815E-20"
        izz="0.00497068788779692" />
    </inertial>
    <visual>
      <origin
        xyz="0 0 0"
        rpy="0 0 0" />
      <geometry>
        <mesh
          filename="package://robot/meshes/LF_2.STL" />
      </geometry>
      <material
        name="">
        <color
          rgba="1 1 1 1" />
      </material>
    </visual>
    <collision>
      <origin
        xyz="0 0 0"
        rpy="0 0 0" />
      <geometry>
        <mesh
          filename="package://robot/meshes/LF_2.STL" />
      </geometry>
    </collision>
  </link>
  <joint
    name="LF_2"
    type="revolute">
    <origin
      xyz="0.2 0 -0.025"
      rpy="0 0 0.58569" />
    <parent
      link="LF_1" />
    <child
      link="LF_2" />
    <axis
      xyz="0 0 -1" />
    <limit
      lower="0"
      upper="0"
      effort="0"
      velocity="0" />
  </joint>
  <link
    name="L">
    <inertial>
      <origin
        xyz="-8.67361737988404E-19 0 0.0150000000000001"
        rpy="0 0 0" />
      <mass
        value="0.763407014822321" />
      <inertia
        ixx="0.00160315473112687"
        ixy="-1.43995601033231E-20"
        ixz="-7.10198537447999E-25"
        iyy="0.00160315473112687"
        iyz="2.95431016671097E-24"
        izz="0.0030917984100304" />
    </inertial>
    <visual>
      <origin
        xyz="0 0 0"
        rpy="0 0 0" />
      <geometry>
        <mesh
          filename="package://robot/meshes/L.STL" />
      </geometry>
      <material
        name="">
        <color
          rgba="1 1 1 1" />
      </material>
    </visual>
    <collision>
      <origin
        xyz="0 0 0"
        rpy="0 0 0" />
      <geometry>
        <mesh
          filename="package://robot/meshes/L.STL" />
      </geometry>
    </collision>
  </link>
  <joint
    name="L"
    type="revolute">
    <origin
      xyz="-0.3 0 -0.0350000000000001"
      rpy="0 0 -0.58568554345715" />
    <parent
      link="LF_2" />
    <child
      link="L" />
    <axis
      xyz="0 0 1" />
    <limit
      lower="0"
      upper="0"
      effort="0"
      velocity="0" />
  </joint>
  <link
    name="RF_1">
    <inertial>
      <origin
        xyz="0.0749790246153108 -5.55111512312578E-17 -0.0168807682307895"
        rpy="0 0 0" />
      <mass
        value="0.395508836352695" />
      <inertia
        ixx="0.000183089900579248"
        ixy="1.76861673227501E-19"
        ixz="-0.000204048265203774"
        iyy="0.0023625702698755"
        iyz="6.28467776911069E-21"
        izz="0.00239345934565496" />
    </inertial>
    <visual>
      <origin
        xyz="0 0 0"
        rpy="0 0 0" />
      <geometry>
        <mesh
          filename="package://robot/meshes/RF_1.STL" />
      </geometry>
      <material
        name="">
        <color
          rgba="1 1 1 1" />
      </material>
    </visual>
    <collision>
      <origin
        xyz="0 0 0"
        rpy="0 0 0" />
      <geometry>
        <mesh
          filename="package://robot/meshes/RF_1.STL" />
      </geometry>
    </collision>
  </link>
  <joint
    name="RF_1"
    type="revolute">
    <origin
      xyz="0.05 0.08 0.21"
      rpy="0 0 0" />
    <parent
      link="base_link" />
    <child
      link="RF_1" />
    <axis
      xyz="0 0 1" />
    <limit
      lower="-0.2617"
      upper="-1.0466"
      effort="0"
      velocity="0" />
  </joint>
  <link
    name="RF_2">
    <inertial>
      <origin
        xyz="-0.15 2.08166817117217E-17 -0.01"
        rpy="0 0 0" />
      <mass
        value="0.444823001646925" />
      <inertia
        ixx="0.000145446900494078"
        ixy="2.98155597433514E-19"
        ixz="5.30143760293279E-05"
        iyy="0.00486196443754988"
        iyz="-1.01643953670516E-20"
        izz="0.00497068788779692" />
    </inertial>
    <visual>
      <origin
        xyz="0 0 0"
        rpy="0 0 0" />
      <geometry>
        <mesh
          filename="package://robot/meshes/RF_2.STL" />
      </geometry>
      <material
        name="">
        <color
          rgba="1 1 1 1" />
      </material>
    </visual>
    <collision>
      <origin
        xyz="0 0 0"
        rpy="0 0 0" />
      <geometry>
        <mesh
          filename="package://robot/meshes/RF_2.STL" />
      </geometry>
    </collision>
  </link>
  <joint
    name="RF_2"
    type="revolute">
    <origin
      xyz="0.2 0 0.025"
      rpy="0 0 0.58568554345715" />
    <parent
      link="RF_1" />
    <child
      link="RF_2" />
    <axis
      xyz="0 0 -1" />
    <limit
      lower="0"
      upper="0"
      effort="0"
      velocity="0" />
  </joint>
  <link
    name="R">
    <inertial>
      <origin
        xyz="-8.67361737988404E-19 0 -0.0149999999999999"
        rpy="0 0 0" />
      <mass
        value="0.763407014822321" />
      <inertia
        ixx="0.00160315473112687"
        ixy="-1.86347248395946E-19"
        ixz="-1.93699604447607E-24"
        iyy="0.00160315473112687"
        iyz="2.42191734012324E-24"
        izz="0.0030917984100304" />
    </inertial>
    <visual>
      <origin
        xyz="0 0 0"
        rpy="0 0 0" />
      <geometry>
        <mesh
          filename="package://robot/meshes/R.STL" />
      </geometry>
      <material
        name="">
        <color
          rgba="1 1 1 1" />
      </material>
    </visual>
    <collision>
      <origin
        xyz="0 0 0"
        rpy="0 0 0" />
      <geometry>
        <mesh
          filename="package://robot/meshes/R.STL" />
      </geometry>
    </collision>
  </link>
  <joint
    name="R"
    type="revolute">
    <origin
      xyz="-0.3 0 0.035"
      rpy="0 0 -0.58568554345715" />
    <parent
      link="RF_2" />
    <child
      link="R" />
    <axis
      xyz="0 0 1" />
    <limit
      lower="0"
      upper="0"
      effort="0"
      velocity="0" />
  </joint>
  <link
    name="RB_1">
    <inertial>
      <origin
        xyz="-0.0912954643793854 -3.88578058618805E-16 -0.0113056803430923"
        rpy="0 0 0" />
      <mass
        value="0.324823001646925" />
      <inertia
        ixx="0.000107013716905788"
        ixy="7.29891813641705E-21"
        ixz="3.87197766270465E-05"
        iyy="0.00180263223873226"
        iyz="1.57649040573712E-22"
        izz="0.00187778887256759" />
    </inertial>
    <visual>
      <origin
        xyz="0 0 0"
        rpy="0 0 0" />
      <geometry>
        <mesh
          filename="package://robot/meshes/RB_1.STL" />
      </geometry>
      <material
        name="">
        <color
          rgba="1 1 1 1" />
      </material>
    </visual>
    <collision>
      <origin
        xyz="0 0 0"
        rpy="0 0 0" />
      <geometry>
        <mesh
          filename="package://robot/meshes/RB_1.STL" />
      </geometry>
    </collision>
  </link>
  <joint
    name="RB_1"
    type="revolute">
    <origin
      xyz="-0.05 0.08 0.185"
      rpy="0 0 0" />
    <parent
      link="base_link" />
    <child
      link="RB_1" />
    <axis
      xyz="0 0 1" />
    <limit
      lower="0.2617"
      upper="1.0466"
      effort="0"
      velocity="0" />
  </joint>
  <link
    name="RB_2">
    <inertial>
      <origin
        xyz="0.15 0 -0.01"
        rpy="0 0 0" />
      <mass
        value="0.444823001646925" />
      <inertia
        ixx="0.000145446900494077"
        ixy="3.9979955110403E-19"
        ixz="-5.30143760293278E-05"
        iyy="0.00486196443754988"
        iyz="1.01643953670516E-20"
        izz="0.00497068788779692" />
    </inertial>
    <visual>
      <origin
        xyz="0 0 0"
        rpy="0 0 0" />
      <geometry>
        <mesh
          filename="package://robot/meshes/RB_2.STL" />
      </geometry>
      <material
        name="">
        <color
          rgba="1 1 1 1" />
      </material>
    </visual>
    <collision>
      <origin
        xyz="0 0 0"
        rpy="0 0 0" />
      <geometry>
        <mesh
          filename="package://robot/meshes/RB_2.STL" />
      </geometry>
    </collision>
  </link>
  <joint
    name="RB_2"
    type="revolute">
    <origin
      xyz="-0.2 0 0.025"
      rpy="0 0 -0.585685543457153" />
    <parent
      link="RB_1" />
    <child
      link="RB_2" />
    <axis
      xyz="0 0 -1" />
    <limit
      lower="0"
      upper="0"
      effort="0"
      velocity="0" />
  </joint>
</robot>